<?xml version='1.0'?>

<robot name="mogi_bot" xmlns:xacro="http://www.ros.org/wiki/xacro">

  <!-- STEP 3 - Gazebo plugin -->
  <xacro:include filename="$(find bme_ros2_navigation)/urdf/mogi_bot.gazebo" />

  <!-- STEP 4 - RViz colors -->
  <xacro:include filename="$(find bme_ros2_navigation)/urdf/materials.xacro" />

  <!-- STEP 1 - Robot chassis -->
  <link name="base_footprint"></link>

  <joint name="base_footprint_joint" type="fixed">
    <origin xyz="0 0 0" rpy="0 0 0" />
    <parent link="base_footprint"/>
    <child link="base_link" />
  </joint>

  <link name='base_link'>
    <pose>0 0 0.1 0 0 0</pose>

    <inertial>
      <mass value="15.0"/>
      <origin xyz="0.0 0 0" rpy=" 0 0 0"/>
      <inertia
          ixx="0.0625" ixy="0" ixz="0"
          iyy="0.2125" iyz="0"
          izz="0.25"
      />
    </inertial>

    <collision name='collision'>
      <origin xyz="0 0 0" rpy=" 0 0 0"/> 
      <geometry>
        <box size=".4 .3 .1"/>
      </geometry>
    </collision>

    <visual name='base_link_visual'>
      <origin xyz="0 0 0" rpy=" 0 0 0"/>
      <geometry>
        <box size=".4 .3 .1"/>
      </geometry>
    </visual>

    <collision name='rear_caster_collision'>
      <origin xyz="-0.15 0 -0.0375" rpy=" 0 0 0"/>
      <geometry>
        <sphere radius="0.0374"/>
      </geometry>
    </collision>

    <visual name='rear_caster_visual'>
      <origin xyz="-0.15 0 -0.0375" rpy=" 0 0 0"/>
      <geometry>
        <sphere radius="0.0375"/>
      </geometry>
    </visual>

    <collision name='front_caster_collision'>
      <origin xyz="0.15 0 -0.0375" rpy=" 0 0 0"/>
      <geometry>
        <sphere radius="0.0374"/>
      </geometry>
    </collision>

    <visual name='front_caster_visual'>
      <origin xyz="0.15 0 -0.0375" rpy=" 0 0 0"/>
      <geometry>
        <sphere radius="0.0375"/>
      </geometry>
    </visual>

  </link>

  <!-- STEP 2 - Wheels -->
  <joint type="continuous" name="left_wheel_joint">
    <origin xyz="0 0.18 0" rpy="0 0 0"/>
    <child link="left_wheel"/>
    <parent link="base_link"/>
    <axis xyz="0 1 0" rpy="0 0 0"/>
    <limit effort="100" velocity="10"/>
    <dynamics damping="1.0" friction="1.0"/>
  </joint>

  <link name='left_wheel'>
    <inertial>
      <mass value="5.0"/>
      <origin xyz="0 0 0" rpy="0 1.5707 1.5707"/>
      <inertia
          ixx="0.0076" ixy="0" ixz="0"
          iyy="0.0076" iyz="0"
          izz="0.0141"
      />
    </inertial>

    <collision>
      <origin xyz="0 0 0" rpy="0 1.5707 1.5707"/> 
      <geometry>
        <cylinder radius=".075" length=".0375"/>
      </geometry>
    </collision>

    <visual name='left_wheel_visual'>
      <origin xyz="0 0 0" rpy="0 1.5707 1.5707"/>
      <geometry>
        <mesh filename = "package://bme_ros2_navigation/meshes/wheel.dae" scale="0.75 0.75 0.75"/>
      </geometry>
    </visual>
  </link>

  <joint type="continuous" name="right_wheel_joint">
    <origin xyz="0 -0.18 0" rpy="0 0 0"/>
    <child link="right_wheel"/>
    <parent link="base_link"/>
    <axis xyz="0 1 0" rpy="0 0 0"/>
    <limit effort="100" velocity="10"/>
    <dynamics damping="1.0" friction="1.0"/>
  </joint>

  <link name='right_wheel'>
    <inertial>
      <mass value="5.0"/>
      <origin xyz="0 0 0" rpy="0 1.5707 1.5707"/>
      <inertia  
          ixx="0.0076" ixy="0" ixz="0"
          iyy="0.0076" iyz="0"
          izz="0.0141"
      />
    </inertial>

    <collision>
      <origin xyz="0 0 0" rpy="0 1.5707 1.5707"/> 
      <geometry>
        <cylinder radius=".075" length=".0375"/>
      </geometry>
    </collision>

    <visual name='right_wheel_visual'>
      <origin xyz="0 0 0" rpy="0 1.5707 1.5707"/>
      <geometry>
        <mesh filename = "package://bme_ros2_navigation/meshes/wheel.dae" scale="0.75 0.75 0.75"/>
      </geometry>
    </visual>
  </link>

  <!-- STEP 4 - Gazebo frictions and colors -->
  <gazebo reference="left_wheel">
    <mu1>0.2</mu1>
    <mu2>0.2</mu2>
    <kp>1000000.0</kp>
    <kd>100.0</kd>
    <minDepth>0.0001</minDepth>
    <maxVel>1.0</maxVel>
  </gazebo>

  <gazebo reference="right_wheel">
    <mu1>0.2</mu1>
    <mu2>0.2</mu2>
    <kp>1000000.0</kp>
    <kd>100.0</kd>
    <minDepth>0.0001</minDepth>
    <maxVel>1.0</maxVel>
  </gazebo>

  <gazebo reference="base_link">
    <mu1>0.000002</mu1>
    <mu2>0.000002</mu2>
  </gazebo>

  <!-- Camera -->
  <joint type="fixed" name="camera_joint">
    <origin xyz="0.215 0 0.035" rpy="0 0 0"/>
    <child link="camera_link"/>
    <parent link="base_link"/>
    <axis xyz="0 1 0" />
  </joint>

  <link name='camera_link'>
    <pose>0 0 0 0 0 0</pose>
    <inertial>
      <mass value="0.1"/>
      <origin xyz="0 0 0" rpy="0 0 0"/>
      <inertia
          ixx="1e-6" ixy="0" ixz="0"
          iyy="1e-6" iyz="0"
          izz="1e-6"
      />
    </inertial>

    <collision name='collision'>
      <origin xyz="0 0 0" rpy="0 0 0"/> 
      <geometry>
        <box size=".03 .03 .03"/>
      </geometry>
    </collision>

    <visual name='camera_link_visual'>
      <origin xyz="0 0 0" rpy="0 0 0"/>
      <geometry>
        <box size=".03 .03 .03"/>
      </geometry>
    </visual>

  </link>

  <gazebo reference="camera_link">
    <material>Gazebo/Red</material>
  </gazebo>

  <joint type="fixed" name="camera_optical_joint">
    <origin xyz="0 0 0" rpy="-1.5707 0 -1.5707"/>
    <child link="camera_link_optical"/>
    <parent link="camera_link"/>
  </joint>

  <link name="camera_link_optical">
  </link>

  <!-- IMU -->
  <joint name="imu_joint" type="fixed">
    <origin xyz="0 0 0" rpy="0 0 0" />
    <parent link="base_link"/>
    <child link="imu_link" />
  </joint>

  <link name="imu_link">
  </link>


  <!-- Lidar -->
  <joint type="fixed" name="scan_joint">
    <origin xyz="0.0 0 0.08" rpy="0 0 0"/>
    <child link="scan_link"/>
    <parent link="base_link"/>
    <axis xyz="0 1 0" rpy="0 0 0"/>
  </joint>

  <link name='scan_link'>
    <inertial>
      <mass value="1e-5"/>
      <origin xyz="0 0 0" rpy="0 0 0"/>
      <inertia
          ixx="1e-6" ixy="0" ixz="0"
          iyy="1e-6" iyz="0"
          izz="1e-6"
      />
    </inertial>
    <collision name='collision'>
      <origin xyz="0 0 0" rpy="0 0 0"/> 
      <geometry>
        <box size=".1 .1 .1"/>
      </geometry>
    </collision>

    <visual name='scan_link_visual'>
      <origin xyz="0 0 0" rpy="0 0 0"/>
      <geometry>
        <mesh filename = "package://bme_ros2_navigation/meshes/lidar.dae"/>
      </geometry>
    </visual>

  </link>

  <gazebo reference="scan_link">
    <selfCollide>false</selfCollide>
    <mu1 value="0.05" />
    <mu2 value="0.05" />
  </gazebo>

    <!-- Attach base link of arm to parent_link -->
    <joint name="arm_base_joint" type="fixed">
        <origin xyz="0.0 0 0.15" rpy="0 0 0"/>
        <parent link="base_link"/>
        <child link="arm_base_link"/>
    </joint>

    <link name="arm_base_link">
        <inertial>
        <mass value="2"/>
        <origin xyz="0.0 0.0 0.0"/>
        <inertia ixx="0.0117" ixy="0.0" ixz="0.0"
                iyy="0.0117" iyz="0.0"
                izz="0.0225"/>
        </inertial>
        <collision>
        <geometry>
            <cylinder radius="0.15" length="0.05"/>
        </geometry>
        <category_bitmask>0x02</category_bitmask>
        <origin xyz="0 0 0"/>
        </collision>
        <visual>
        <geometry>
            <cylinder radius="0.15" length="0.05"/>
        </geometry>
        <material name="grey"/>
        <origin xyz="0 0 0"/>
        </visual>
    </link>

    <!-- Arm chain follows here -->
    <!-- Everything else stays the same, but change 'base_link' to 'arm_base_link' -->
    <!-- So shoulder connects to arm_base_link -->

    <!-- Replace 'base_link' below with 'arm_base_link' -->

    <!-- Shoulder joint -->
    <joint name="shoulder_pan_joint" type="revolute">
        <limit lower="-3.14" upper="3.14" effort="330.0" velocity="3.14"/>
        <parent link="arm_base_link"/>
        <child link="shoulder_link"/>
        <axis xyz="0 0 1"/>
        <origin xyz="0 0 0.05"/>
    </joint>

    <!-- Shoulder link -->
    <link name="shoulder_link">
        <inertial>
        <mass value="0.5"/>
        <origin xyz="0.0 0.0 0.0" rpy="0.0 0.0 0.0"/>
        <inertia ixx="0.0014" ixy="0.0" ixz="0.0"
                iyy="0.0014" iyz="0.0"
                izz="0.0025"
        />
        </inertial>
        <collision>
        <geometry>
            <cylinder radius="0.1" length="0.05"/>
        </geometry>
        <category_bitmask>0x02</category_bitmask>
        <origin xyz="0.0 0.0 0.0" rpy="0.0 0.0 0.0"/>
        </collision>
        <visual>
        <geometry>
            <mesh filename = "package://bme_ros2_navigation/meshes/shoulder.dae"/>
        </geometry>
        <material name="orange"/>
        <origin xyz="0.0 0.0 0.0" rpy="0.0 0.0 0.0"/>
        </visual>
    </link>

    <!-- Shoulder lift joint -->
    <joint name="shoulder_lift_joint" type="revolute">
        <limit lower="-1.5708" upper="1.5708" effort="330.0" velocity="3.14"/>
        <parent link="shoulder_link"/>
        <child link="upper_arm_link"/>
        <axis xyz="0 1 0"/>
        <origin xyz="0.0 0.0 0.025" rpy="0.0 0.0 0.0"/>
        <dynamics damping="0.0" friction="0.0"/>
    </joint>

    <!-- Upper arm link -->
    <link name="upper_arm_link">
        <inertial>
        <mass value="0.3"/>
        <origin xyz="0.0 0.0 0.1" rpy="0.0 0.0 0.0"/>
        <inertia ixx="0.0012" ixy="0.0" ixz="0.0"
                iyy="0.0012" iyz="0.0"
                izz="0.0004"
        />
        </inertial>
        <collision>
        <geometry>
            <cylinder radius="0.05" length="0.2"/>
        </geometry>
        <category_bitmask>0x02</category_bitmask>
        <origin xyz="0.0 0.0 0.1" rpy="0.0 0.0 0.0"/>
        </collision>
        <visual>
        <geometry>
            <mesh filename = "package://bme_ros2_navigation/meshes/upper_arm.dae"/>
        </geometry>
        <material name="orange"/>
        <origin xyz="0.0 0.0 0.1" rpy="0.0 0.0 0.0"/>
        </visual>
    </link>
        <!-- STEP 5 - Elbow -->
    <joint name="elbow_joint" type="revolute">
        <limit lower="-2.3562" upper="2.3562" effort="150.0" velocity="3.14"/>
        <parent link="upper_arm_link"/>
        <child link="forearm_link"/>
        <axis xyz="0 1 0"/>
        <origin xyz="0.0 0.0 0.2" rpy="0.0 0.0 0.0"/>
        <dynamics damping="0.0" friction="0.0"/>
    </joint>

    <!-- Forearm link -->
    <link name="forearm_link">
        <inertial>
        <mass value="0.2"/>
        <origin xyz="0.0 0.0 0.125" rpy="0.0 0.0 0.0"/>
        <inertia ixx="0.0011" ixy="0.0" ixz="0.0"
                iyy="0.0011" iyz="0.0"
                izz="0.0004"
        />
        </inertial>
        <collision>
        <geometry>
            <cylinder radius="0.025" length="0.25"/>
        </geometry>
        <category_bitmask>0x02</category_bitmask>
        <origin xyz="0.0 0.0 0.125" rpy="0.0 0.0 0.0"/>
        </collision>
        <visual>
        <geometry>
            <mesh filename = "package://bme_ros2_navigation/meshes/forearm.dae"/>
        </geometry>
        <material name="orange"/>
        <origin xyz="0.0 0.0 0.125" rpy="0.0 0.0 0.0"/>
        </visual>
    </link>
        <!-- STEP 6 - Wrist -->
    <joint name="wrist_joint" type="revolute">
        <limit lower="-2.3562" upper="2.3562" effort="54.0" velocity="3.14"/>
        <parent link="forearm_link"/>
        <child link="wrist_link"/>
        <axis xyz="0 1 0"/>
        <origin xyz="0.0 0.0 0.25" rpy="0.0 0.0 0.0"/>
        <dynamics damping="0.0" friction="0.0"/>
    </joint>

    <!-- Wrist link -->
    <link name="wrist_link">
        <inertial>
        <mass value="0.1"/>
        <origin xyz="0.0 0.0 0.05" rpy="0.0 0.0 0.0"/>
        <inertia ixx="0.00009" ixy="0.0" ixz="0.0"
                iyy="0.00009" iyz="0.0"
                izz="0.00002"
        />
        </inertial>
        <collision>
        <geometry>
            <cylinder radius="0.02" length="0.1"/>
        </geometry>
        <category_bitmask>0x02</category_bitmask>
        <origin xyz="0.0 0.0 0.05" rpy="0.0 0.0 0.0"/>
        </collision>
        <visual>
        <geometry>
        <mesh filename = "package://bme_ros2_navigation/meshes/wrist.dae"/>
        </geometry>
        <material name="orange"/>
        <origin xyz="0.0 0.0 0.05" rpy="0.0 0.0 0.0"/>
        </visual>
    </link>
        <!-- STEP 7 - Gripper -->
    <joint name="gripper_base_joint" type="fixed">
        <parent link="wrist_link"/>
        <child link="gripper_base"/>
        <origin xyz="0.0 0 0.105" rpy="0.0 0 0"/> 
    </joint>

    <!-- Gripper base link -->
    <link name="gripper_base">
        <inertial>
        <mass value="0.1"/>
        <origin xyz="0.0 0.0 0.0" rpy="0.0 0.0 0.0"/>
        <inertia ixx="0.00009" ixy="0.0" ixz="0.0"
                iyy="0.00009" iyz="0.0"
                izz="0.00002"
        />
        </inertial>
        <collision>
        <geometry>
            <box size=".05 .1 .01"/>
        </geometry>
        <category_bitmask>0x02</category_bitmask>
        <origin xyz="0.0 0.0 0.0" rpy="0.0 0.0 0.0"/>
        </collision>
        <visual>
        <geometry>
            <box size=".05 .1 .01"/>
        </geometry>
        <material name="grey"/>
        <origin xyz="0.0 0.0 0.0" rpy="0.0 0.0 0.0"/>
        </visual>
    </link>

    <!-- Left finger joint -->
    <joint name="left_finger_joint" type="prismatic">
        <limit lower="0" upper="0.04" effort="100.0" velocity="4.0"/>
        <parent link="gripper_base"/>
        <child link="left_finger"/>
        <axis xyz="0 1 0"/>
        <origin xyz="0.0 0.01 0.045" />
    </joint>

    <!-- Left finger link -->
    <link name="left_finger">
        <inertial>
        <mass value="0.1"/>
        <origin xyz="0.0 0.0 0.0" rpy="0.0 0.0 0.0"/>
        <inertia ixx="0.00009" ixy="0.0" ixz="0.0"
                iyy="0.00009" iyz="0.0"
                izz="0.00002"
        />
        </inertial>
        <collision>
        <geometry>
            <box size=".04 .01 .08"/>
        </geometry>
        <category_bitmask>0x02</category_bitmask>
        <origin xyz="0.0 0.0 0.0" rpy="0.0 0.0 0.0"/>
        </collision>
        <visual>
        <geometry>
            <box size=".04 .01 .08"/>
        </geometry>
        <material name="blue"/>
        <origin xyz="0.0 0.0 0.0" rpy="0.0 0.0 0.0"/>
        </visual>
    </link>

    <gazebo reference="left_finger">
        <kp>1000000.0</kp>
        <kd>100.0</kd>
        <mu1>15</mu1>
        <mu2>15</mu2>
        <fdir1>1 0 0</fdir1>
        <maxVel>1.0</maxVel>
        <minDepth>0.002</minDepth>
    </gazebo>

    <!-- Right finger joint -->
    <joint name="right_finger_joint" type="prismatic">
        <limit lower="0" upper="0.04" effort="100.0" velocity="4.0"/>
        <parent link="gripper_base"/>
        <child link="right_finger"/>
        <axis xyz="0 -1 0"/>
        <origin xyz="0.0 -0.01 0.045" />
    </joint>

    <!-- Right finger link -->
    <link name="right_finger">
        <inertial>
        <mass value="0.1"/>
        <origin xyz="0.0 0.0 0.0" rpy="0.0 0.0 0.0"/>
        <inertia ixx="0.00009" ixy="0.0" ixz="0.0"
                iyy="0.00009" iyz="0.0"
                izz="0.00002"
        />
        </inertial>
        <collision>
        <geometry>
            <box size=".04 .01 .08"/>
        </geometry>
        <category_bitmask>0x02</category_bitmask>
        <origin xyz="0.0 0.0 0.0" rpy="0.0 0.0 0.0"/>
        </collision>
        <visual>
        <geometry>
            <box size=".04 .01 .08"/>
        </geometry>
        <material name="blue"/>
        <origin xyz="0.0 0.0 0.0" rpy="0.0 0.0 0.0"/>
        </visual>
    </link>

    <gazebo reference="right_finger">
        <kp>1000000.0</kp>
        <kd>100.0</kd>
        <mu1>15</mu1>
        <mu2>15</mu2>
        <fdir1>1 0 0</fdir1>
        <maxVel>1.0</maxVel>
        <minDepth>0.002</minDepth>
    </gazebo>

        <!-- STEP 8 - Gazebo plugin -->
    <xacro:include filename="$(find bme_ros2_navigation)/urdf/mogi_arm.gazebo" />
        <!-- STEP 9 - ROS2 control -->
    <ros2_control name="GazeboSystem" type="system">
        <hardware>
        <plugin>gz_ros2_control/GazeboSimSystem</plugin>
        </hardware>
        <joint name="shoulder_pan_joint">
        <command_interface name="position">
            <param name="min">-2</param>
            <param name="max">2</param>
        </command_interface>
        <state_interface name="position">
            <param name="initial_value">0.0</param>
        </state_interface>
        <state_interface name="velocity"/>
        <state_interface name="effort"/>
        </joint>
        <joint name="shoulder_lift_joint">
        <command_interface name="position">
            <param name="min">-2</param>
            <param name="max">2</param>
        </command_interface>
        <state_interface name="position">
            <param name="initial_value">0.0</param>
        </state_interface>
        <state_interface name="velocity"/>
        <state_interface name="effort"/>
        </joint>
        <joint name="elbow_joint">
        <command_interface name="position">
            <param name="min">-2</param>
            <param name="max">2</param>
        </command_interface>
        <state_interface name="position">
            <param name="initial_value">0.0</param>
        </state_interface>
        <state_interface name="velocity"/>
        <state_interface name="effort"/>
        </joint>
        <joint name="wrist_joint">
        <command_interface name="position">
            <param name="min">-2</param>
            <param name="max">2</param>
        </command_interface>
        <state_interface name="position">
            <param name="initial_value">0.0</param>
        </state_interface>
        <state_interface name="velocity"/>
        <state_interface name="effort"/>
        </joint>
        <joint name="left_finger_joint">
        <command_interface name="position">
            <param name="min">-2</param>
            <param name="max">2</param>
        </command_interface>
        <state_interface name="position">
            <param name="initial_value">0.0</param>
        </state_interface>
        <state_interface name="velocity"/>
        <state_interface name="effort"/>
        </joint>
        <joint name="right_finger_joint">
        <command_interface name="position">
            <param name="min">-2</param>
            <param name="max">2</param>
        </command_interface>
        <state_interface name="position">
            <param name="initial_value">0.0</param>
        </state_interface>
        <state_interface name="velocity"/>
        <state_interface name="effort"/>
        </joint>
    </ros2_control>

        <!-- STEP 10 - End effector -->
    <joint name="end_effector_joint" type="fixed">
        <origin xyz="0.0 0.0 0.175" rpy="0 0 0"/>
        <parent link="wrist_link"/>
        <child link="end_effector_link"/>
    </joint>

    <!-- End effector link -->
    <link name="end_effector_link">
        <visual>
        <origin xyz="0 0 0" rpy="0 0 0"/>
        <geometry>
            <box size="0.01 0.01 0.01" />
        </geometry>
        <material name="red"/>
        </visual>

        <inertial>
        <origin xyz="0 0 0" />
        <mass value="1.0e-03" />
        <inertia ixx="1.0e-03" ixy="0.0" ixz="0.0"
                iyy="1.0e-03" iyz="0.0"
                izz="1.0e-03" />
        </inertial>
    </link>

</robot>